[2024-01-05T04:24:32.032+0000] {taskinstance.py:1957} INFO - Dependencies all met for dep_context=non-requeueable deps ti=<TaskInstance: thangnc_dag01a.print_date manual__2024-01-05T04:24:29.687704+00:00 [queued]>
[2024-01-05T04:24:32.041+0000] {taskinstance.py:1957} INFO - Dependencies all met for dep_context=requeueable deps ti=<TaskInstance: thangnc_dag01a.print_date manual__2024-01-05T04:24:29.687704+00:00 [queued]>
[2024-01-05T04:24:32.042+0000] {taskinstance.py:2171} INFO - Starting attempt 1 of 2
[2024-01-05T04:24:32.053+0000] {taskinstance.py:2192} INFO - Executing <Task(BashOperator): print_date> on 2024-01-05 04:24:29.687704+00:00
[2024-01-05T04:24:32.073+0000] {standard_task_runner.py:60} INFO - Started process 64 to run task
[2024-01-05T04:24:32.085+0000] {standard_task_runner.py:87} INFO - Running: ['***', 'tasks', 'run', 'thangnc_dag01a', 'print_date', 'manual__2024-01-05T04:24:29.687704+00:00', '--job-id', '15', '--raw', '--subdir', 'DAGS_FOLDER/test_dag.py', '--cfg-path', '/tmp/tmpm79op6qe']
[2024-01-05T04:24:32.102+0000] {standard_task_runner.py:88} INFO - Job 15: Subtask print_date
[2024-01-05T04:24:32.295+0000] {task_command.py:423} INFO - Running <TaskInstance: thangnc_dag01a.print_date manual__2024-01-05T04:24:29.687704+00:00 [running]> on host fed638a2c175
[2024-01-05T04:24:32.442+0000] {taskinstance.py:2481} INFO - Exporting env vars: AIRFLOW_CTX_DAG_EMAIL='thangnch@gmail.com' AIRFLOW_CTX_DAG_OWNER='***' AIRFLOW_CTX_DAG_ID='thangnc_dag01a' AIRFLOW_CTX_TASK_ID='print_date' AIRFLOW_CTX_EXECUTION_DATE='2024-01-05T04:24:29.687704+00:00' AIRFLOW_CTX_TRY_NUMBER='1' AIRFLOW_CTX_DAG_RUN_ID='manual__2024-01-05T04:24:29.687704+00:00'
[2024-01-05T04:24:32.456+0000] {subprocess.py:63} INFO - Tmp dir root location: /tmp
[2024-01-05T04:24:32.464+0000] {subprocess.py:75} INFO - Running command: ['/usr/bin/bash', '-c', 'date > /home/thangnc/date.txt']
[2024-01-05T04:24:32.488+0000] {subprocess.py:86} INFO - Output:
[2024-01-05T04:24:32.496+0000] {subprocess.py:93} INFO - /usr/bin/bash: line 1: /home/thangnc/date.txt: No such file or directory
[2024-01-05T04:24:32.499+0000] {subprocess.py:97} INFO - Command exited with return code 1
[2024-01-05T04:24:32.519+0000] {taskinstance.py:2699} ERROR - Task failed with exception
Traceback (most recent call last):
  File "/home/airflow/.local/lib/python3.8/site-packages/airflow/models/taskinstance.py", line 433, in _execute_task
    result = execute_callable(context=context, **execute_callable_kwargs)
  File "/home/airflow/.local/lib/python3.8/site-packages/airflow/operators/bash.py", line 212, in execute
    raise AirflowException(
airflow.exceptions.AirflowException: Bash command failed. The command returned a non-zero exit code 1.
[2024-01-05T04:24:32.524+0000] {taskinstance.py:1138} INFO - Marking task as UP_FOR_RETRY. dag_id=thangnc_dag01a, task_id=print_date, execution_date=20240105T042429, start_date=20240105T042432, end_date=20240105T042432
[2024-01-05T04:24:32.542+0000] {warnings.py:109} WARNING - /home/***/.local/lib/python3.8/site-packages/***/utils/email.py:154: RemovedInAirflow3Warning: Fetching SMTP credentials from configuration variables will be deprecated in a future release. Please set credentials using a connection instead.
  send_mime_email(e_from=mail_from, e_to=recipients, mime_msg=msg, conn_id=conn_id, dryrun=dryrun)

[2024-01-05T04:24:32.544+0000] {configuration.py:1046} WARNING - section/key [smtp/smtp_user] not found in config
[2024-01-05T04:24:32.545+0000] {email.py:270} INFO - Email alerting: attempt 1
[2024-01-05T04:24:32.562+0000] {configuration.py:1046} WARNING - section/key [smtp/smtp_user] not found in config
[2024-01-05T04:24:32.564+0000] {email.py:270} INFO - Email alerting: attempt 1
[2024-01-05T04:24:32.566+0000] {taskinstance.py:826} ERROR - Failed to send email to: ['thangnch@gmail.com']
Traceback (most recent call last):
  File "/home/airflow/.local/lib/python3.8/site-packages/airflow/models/taskinstance.py", line 2335, in _run_raw_task
    self._execute_task_with_callbacks(context, test_mode, session=session)
  File "/home/airflow/.local/lib/python3.8/site-packages/airflow/models/taskinstance.py", line 2500, in _execute_task_with_callbacks
    result = self._execute_task(context, task_orig)
  File "/home/airflow/.local/lib/python3.8/site-packages/airflow/models/taskinstance.py", line 2517, in _execute_task
    return _execute_task(self, context, task_orig)
  File "/home/airflow/.local/lib/python3.8/site-packages/airflow/models/taskinstance.py", line 433, in _execute_task
    result = execute_callable(context=context, **execute_callable_kwargs)
  File "/home/airflow/.local/lib/python3.8/site-packages/airflow/operators/bash.py", line 212, in execute
    raise AirflowException(
airflow.exceptions.AirflowException: Bash command failed. The command returned a non-zero exit code 1.

During handling of the above exception, another exception occurred:

Traceback (most recent call last):
  File "/home/airflow/.local/lib/python3.8/site-packages/airflow/models/taskinstance.py", line 1000, in _email_alert
    send_email(task.email, subject, html_content)
  File "/home/airflow/.local/lib/python3.8/site-packages/airflow/utils/email.py", line 80, in send_email
    return backend(
  File "/home/airflow/.local/lib/python3.8/site-packages/airflow/utils/email.py", line 154, in send_email_smtp
    send_mime_email(e_from=mail_from, e_to=recipients, mime_msg=msg, conn_id=conn_id, dryrun=dryrun)
  File "/home/airflow/.local/lib/python3.8/site-packages/airflow/utils/email.py", line 272, in send_mime_email
    smtp_conn = _get_smtp_connection(smtp_host, smtp_port, smtp_timeout, smtp_ssl)
  File "/home/airflow/.local/lib/python3.8/site-packages/airflow/utils/email.py", line 316, in _get_smtp_connection
    return smtplib.SMTP(host=host, port=port, timeout=timeout)
  File "/usr/local/lib/python3.8/smtplib.py", line 255, in __init__
    (code, msg) = self.connect(host, port)
  File "/usr/local/lib/python3.8/smtplib.py", line 339, in connect
    self.sock = self._get_socket(host, port, self.timeout)
  File "/usr/local/lib/python3.8/smtplib.py", line 310, in _get_socket
    return socket.create_connection((host, port), timeout,
  File "/usr/local/lib/python3.8/socket.py", line 808, in create_connection
    raise err
  File "/usr/local/lib/python3.8/socket.py", line 796, in create_connection
    sock.connect(sa)
OSError: [Errno 99] Cannot assign requested address

During handling of the above exception, another exception occurred:

Traceback (most recent call last):
  File "/home/airflow/.local/lib/python3.8/site-packages/airflow/models/taskinstance.py", line 824, in _handle_failure
    task_instance.email_alert(error, failure_context["task"])
  File "/home/airflow/.local/lib/python3.8/site-packages/airflow/models/taskinstance.py", line 2947, in email_alert
    _email_alert(task_instance=self, exception=exception, task=task)
  File "/home/airflow/.local/lib/python3.8/site-packages/airflow/models/taskinstance.py", line 1002, in _email_alert
    send_email(task.email, subject, html_content_err)
  File "/home/airflow/.local/lib/python3.8/site-packages/airflow/utils/email.py", line 80, in send_email
    return backend(
  File "/home/airflow/.local/lib/python3.8/site-packages/airflow/utils/email.py", line 154, in send_email_smtp
    send_mime_email(e_from=mail_from, e_to=recipients, mime_msg=msg, conn_id=conn_id, dryrun=dryrun)
  File "/home/airflow/.local/lib/python3.8/site-packages/airflow/utils/email.py", line 272, in send_mime_email
    smtp_conn = _get_smtp_connection(smtp_host, smtp_port, smtp_timeout, smtp_ssl)
  File "/home/airflow/.local/lib/python3.8/site-packages/airflow/utils/email.py", line 316, in _get_smtp_connection
    return smtplib.SMTP(host=host, port=port, timeout=timeout)
  File "/usr/local/lib/python3.8/smtplib.py", line 255, in __init__
    (code, msg) = self.connect(host, port)
  File "/usr/local/lib/python3.8/smtplib.py", line 339, in connect
    self.sock = self._get_socket(host, port, self.timeout)
  File "/usr/local/lib/python3.8/smtplib.py", line 310, in _get_socket
    return socket.create_connection((host, port), timeout,
  File "/usr/local/lib/python3.8/socket.py", line 808, in create_connection
    raise err
  File "/usr/local/lib/python3.8/socket.py", line 796, in create_connection
    sock.connect(sa)
OSError: [Errno 99] Cannot assign requested address
[2024-01-05T04:24:32.580+0000] {standard_task_runner.py:107} ERROR - Failed to execute job 15 for task print_date (Bash command failed. The command returned a non-zero exit code 1.; 64)
[2024-01-05T04:24:32.613+0000] {local_task_job_runner.py:234} INFO - Task exited with return code 1
[2024-01-05T04:24:32.633+0000] {taskinstance.py:3281} INFO - 0 downstream tasks scheduled from follow-on schedule check
