[2024-01-06T08:42:27.118+0000] {taskinstance.py:1957} INFO - Dependencies all met for dep_context=non-requeueable deps ti=<TaskInstance: data_ds.sleep manual__2024-01-06T08:42:18.979858+00:00 [queued]>
[2024-01-06T08:42:27.167+0000] {taskinstance.py:1957} INFO - Dependencies all met for dep_context=requeueable deps ti=<TaskInstance: data_ds.sleep manual__2024-01-06T08:42:18.979858+00:00 [queued]>
[2024-01-06T08:42:27.171+0000] {taskinstance.py:2171} INFO - Starting attempt 1 of 4
[2024-01-06T08:42:27.213+0000] {taskinstance.py:2192} INFO - Executing <Task(BashOperator): sleep> on 2024-01-06 08:42:18.979858+00:00
[2024-01-06T08:42:27.274+0000] {standard_task_runner.py:60} INFO - Started process 172 to run task
[2024-01-06T08:42:27.325+0000] {standard_task_runner.py:87} INFO - Running: ['***', 'tasks', 'run', 'data_ds', 'sleep', 'manual__2024-01-06T08:42:18.979858+00:00', '--job-id', '37', '--raw', '--subdir', 'DAGS_FOLDER/test.py', '--cfg-path', '/tmp/tmp3md6riyi']
[2024-01-06T08:42:27.360+0000] {standard_task_runner.py:88} INFO - Job 37: Subtask sleep
[2024-01-06T08:42:27.802+0000] {task_command.py:423} INFO - Running <TaskInstance: data_ds.sleep manual__2024-01-06T08:42:18.979858+00:00 [running]> on host fed638a2c175
[2024-01-06T08:42:28.153+0000] {taskinstance.py:2481} INFO - Exporting env vars: AIRFLOW_CTX_DAG_EMAIL='thangnch@gmail.com' AIRFLOW_CTX_DAG_OWNER='***' AIRFLOW_CTX_DAG_ID='data_ds' AIRFLOW_CTX_TASK_ID='sleep' AIRFLOW_CTX_EXECUTION_DATE='2024-01-06T08:42:18.979858+00:00' AIRFLOW_CTX_TRY_NUMBER='1' AIRFLOW_CTX_DAG_RUN_ID='manual__2024-01-06T08:42:18.979858+00:00'
[2024-01-06T08:42:28.190+0000] {subprocess.py:63} INFO - Tmp dir root location: /tmp
[2024-01-06T08:42:28.211+0000] {subprocess.py:75} INFO - Running command: ['/usr/bin/bash', '-c', 'python3 /opt/***/dags/index_data/index_to_es.py']
[2024-01-06T08:42:28.449+0000] {subprocess.py:86} INFO - Output:
[2024-01-06T08:42:40.708+0000] {subprocess.py:93} INFO - /opt/***/dags/index_data/index_to_es.py:67: DeprecationWarning: Passing transport options in the API method is deprecated. Use 'Elasticsearch.options()' instead.
[2024-01-06T08:42:40.722+0000] {subprocess.py:93} INFO -   helpers.bulk(es_client, result, index=index_name, request_timeout=200)
[2024-01-06T08:42:40.725+0000] {subprocess.py:93} INFO -              GAME_DATE_EST   GAME_ID  ... REB_away  HOME_TEAM_WINS
[2024-01-06T08:42:40.726+0000] {subprocess.py:93} INFO - 0               2022-03-12  22101005  ...     46.0               0
[2024-01-06T08:42:40.734+0000] {subprocess.py:93} INFO - 1               2022-03-12  22101006  ...     40.0               1
[2024-01-06T08:42:40.738+0000] {subprocess.py:93} INFO - 2               2022-03-12  22101007  ...     47.0               0
[2024-01-06T08:42:40.742+0000] {subprocess.py:93} INFO - 3               2022-03-12  22101008  ...     39.0               1
[2024-01-06T08:42:40.756+0000] {subprocess.py:93} INFO - 4               2022-03-12  22101009  ...     50.0               0
[2024-01-06T08:42:40.759+0000] {subprocess.py:93} INFO - ...                    ...       ...  ...      ...             ...
[2024-01-06T08:42:40.760+0000] {subprocess.py:93} INFO - 27758  2023-10-28 00:00:00  22300091  ...     48.0               0
[2024-01-06T08:42:40.761+0000] {subprocess.py:93} INFO - 27759  2023-10-28 00:00:00  22300088  ...     33.0               1
[2024-01-06T08:42:40.763+0000] {subprocess.py:93} INFO - 27760  2023-10-28 00:00:00  22300094  ...     45.0               1
[2024-01-06T08:42:40.764+0000] {subprocess.py:93} INFO - 27761  2023-10-28 00:00:00  22300093  ...     42.0               1
[2024-01-06T08:42:40.765+0000] {subprocess.py:93} INFO - 27762  2023-10-28 00:00:00  22300092  ...     42.0               0
[2024-01-06T08:42:40.766+0000] {subprocess.py:93} INFO - 
[2024-01-06T08:42:40.769+0000] {subprocess.py:93} INFO - [27763 rows x 21 columns]
[2024-01-06T08:42:40.770+0000] {subprocess.py:93} INFO - Indexing into http://172.18.0.2:9200 with index test_data_ds
[2024-01-06T08:42:40.770+0000] {subprocess.py:93} INFO - batch 1
[2024-01-06T08:42:40.773+0000] {subprocess.py:93} INFO - batch 2
[2024-01-06T08:42:40.784+0000] {subprocess.py:93} INFO - batch 3
[2024-01-06T08:42:40.786+0000] {subprocess.py:93} INFO - batch 4
[2024-01-06T08:42:40.787+0000] {subprocess.py:93} INFO - batch 5
[2024-01-06T08:42:40.789+0000] {subprocess.py:93} INFO - batch 6
[2024-01-06T08:42:40.796+0000] {subprocess.py:93} INFO - batch 7
[2024-01-06T08:42:40.804+0000] {subprocess.py:93} INFO - batch 8
[2024-01-06T08:42:40.806+0000] {subprocess.py:93} INFO - batch 9
[2024-01-06T08:42:40.807+0000] {subprocess.py:93} INFO - batch 10
[2024-01-06T08:42:40.808+0000] {subprocess.py:93} INFO - batch 11
[2024-01-06T08:42:40.810+0000] {subprocess.py:93} INFO - batch 12
[2024-01-06T08:42:40.811+0000] {subprocess.py:93} INFO - batch 13
[2024-01-06T08:42:40.812+0000] {subprocess.py:93} INFO - batch 14
[2024-01-06T08:42:40.812+0000] {subprocess.py:93} INFO - batch 15
[2024-01-06T08:42:40.813+0000] {subprocess.py:93} INFO - batch 16
[2024-01-06T08:42:40.815+0000] {subprocess.py:93} INFO - batch 17
[2024-01-06T08:42:40.817+0000] {subprocess.py:93} INFO - batch 18
[2024-01-06T08:42:40.820+0000] {subprocess.py:93} INFO - Traceback (most recent call last):
[2024-01-06T08:42:40.821+0000] {subprocess.py:93} INFO -   File "/opt/***/dags/index_data/index_to_es.py", line 88, in <module>
[2024-01-06T08:42:40.822+0000] {subprocess.py:93} INFO -     index_data(df)
[2024-01-06T08:42:40.823+0000] {subprocess.py:93} INFO -   File "/opt/***/dags/index_data/index_to_es.py", line 67, in index_data
[2024-01-06T08:42:40.824+0000] {subprocess.py:93} INFO -     helpers.bulk(es_client, result, index=index_name, request_timeout=200)
[2024-01-06T08:42:40.825+0000] {subprocess.py:93} INFO -   File "/home/***/.local/lib/python3.8/site-packages/elasticsearch/helpers/actions.py", line 521, in bulk
[2024-01-06T08:42:40.825+0000] {subprocess.py:93} INFO -     for ok, item in streaming_bulk(
[2024-01-06T08:42:40.826+0000] {subprocess.py:93} INFO -   File "/home/***/.local/lib/python3.8/site-packages/elasticsearch/helpers/actions.py", line 436, in streaming_bulk
[2024-01-06T08:42:40.827+0000] {subprocess.py:93} INFO -     for data, (ok, info) in zip(
[2024-01-06T08:42:40.828+0000] {subprocess.py:93} INFO -   File "/home/***/.local/lib/python3.8/site-packages/elasticsearch/helpers/actions.py", line 355, in _process_bulk_chunk
[2024-01-06T08:42:40.829+0000] {subprocess.py:93} INFO -     yield from gen
[2024-01-06T08:42:40.830+0000] {subprocess.py:93} INFO -   File "/home/***/.local/lib/python3.8/site-packages/elasticsearch/helpers/actions.py", line 274, in _process_bulk_chunk_success
[2024-01-06T08:42:40.831+0000] {subprocess.py:93} INFO -     raise BulkIndexError(f"{len(errors)} document(s) failed to index.", errors)
[2024-01-06T08:42:40.832+0000] {subprocess.py:93} INFO - elasticsearch.helpers.BulkIndexError: 99 document(s) failed to index.
[2024-01-06T08:42:41.243+0000] {subprocess.py:97} INFO - Command exited with return code 1
[2024-01-06T08:42:41.355+0000] {taskinstance.py:2699} ERROR - Task failed with exception
Traceback (most recent call last):
  File "/home/airflow/.local/lib/python3.8/site-packages/airflow/models/taskinstance.py", line 433, in _execute_task
    result = execute_callable(context=context, **execute_callable_kwargs)
  File "/home/airflow/.local/lib/python3.8/site-packages/airflow/operators/bash.py", line 212, in execute
    raise AirflowException(
airflow.exceptions.AirflowException: Bash command failed. The command returned a non-zero exit code 1.
[2024-01-06T08:42:41.378+0000] {taskinstance.py:1138} INFO - Marking task as UP_FOR_RETRY. dag_id=data_ds, task_id=sleep, execution_date=20240106T084218, start_date=20240106T084227, end_date=20240106T084241
[2024-01-06T08:42:41.467+0000] {warnings.py:109} WARNING - /home/***/.local/lib/python3.8/site-packages/***/utils/email.py:154: RemovedInAirflow3Warning: Fetching SMTP credentials from configuration variables will be deprecated in a future release. Please set credentials using a connection instead.
  send_mime_email(e_from=mail_from, e_to=recipients, mime_msg=msg, conn_id=conn_id, dryrun=dryrun)

[2024-01-06T08:42:41.471+0000] {configuration.py:1046} WARNING - section/key [smtp/smtp_user] not found in config
[2024-01-06T08:42:41.473+0000] {email.py:270} INFO - Email alerting: attempt 1
[2024-01-06T08:42:41.495+0000] {configuration.py:1046} WARNING - section/key [smtp/smtp_user] not found in config
[2024-01-06T08:42:41.498+0000] {email.py:270} INFO - Email alerting: attempt 1
[2024-01-06T08:42:41.501+0000] {taskinstance.py:826} ERROR - Failed to send email to: ['thangnch@gmail.com']
Traceback (most recent call last):
  File "/home/airflow/.local/lib/python3.8/site-packages/airflow/models/taskinstance.py", line 2335, in _run_raw_task
    self._execute_task_with_callbacks(context, test_mode, session=session)
  File "/home/airflow/.local/lib/python3.8/site-packages/airflow/models/taskinstance.py", line 2500, in _execute_task_with_callbacks
    result = self._execute_task(context, task_orig)
  File "/home/airflow/.local/lib/python3.8/site-packages/airflow/models/taskinstance.py", line 2517, in _execute_task
    return _execute_task(self, context, task_orig)
  File "/home/airflow/.local/lib/python3.8/site-packages/airflow/models/taskinstance.py", line 433, in _execute_task
    result = execute_callable(context=context, **execute_callable_kwargs)
  File "/home/airflow/.local/lib/python3.8/site-packages/airflow/operators/bash.py", line 212, in execute
    raise AirflowException(
airflow.exceptions.AirflowException: Bash command failed. The command returned a non-zero exit code 1.

During handling of the above exception, another exception occurred:

Traceback (most recent call last):
  File "/home/airflow/.local/lib/python3.8/site-packages/airflow/models/taskinstance.py", line 1000, in _email_alert
    send_email(task.email, subject, html_content)
  File "/home/airflow/.local/lib/python3.8/site-packages/airflow/utils/email.py", line 80, in send_email
    return backend(
  File "/home/airflow/.local/lib/python3.8/site-packages/airflow/utils/email.py", line 154, in send_email_smtp
    send_mime_email(e_from=mail_from, e_to=recipients, mime_msg=msg, conn_id=conn_id, dryrun=dryrun)
  File "/home/airflow/.local/lib/python3.8/site-packages/airflow/utils/email.py", line 272, in send_mime_email
    smtp_conn = _get_smtp_connection(smtp_host, smtp_port, smtp_timeout, smtp_ssl)
  File "/home/airflow/.local/lib/python3.8/site-packages/airflow/utils/email.py", line 316, in _get_smtp_connection
    return smtplib.SMTP(host=host, port=port, timeout=timeout)
  File "/usr/local/lib/python3.8/smtplib.py", line 255, in __init__
    (code, msg) = self.connect(host, port)
  File "/usr/local/lib/python3.8/smtplib.py", line 339, in connect
    self.sock = self._get_socket(host, port, self.timeout)
  File "/usr/local/lib/python3.8/smtplib.py", line 310, in _get_socket
    return socket.create_connection((host, port), timeout,
  File "/usr/local/lib/python3.8/socket.py", line 808, in create_connection
    raise err
  File "/usr/local/lib/python3.8/socket.py", line 796, in create_connection
    sock.connect(sa)
OSError: [Errno 99] Cannot assign requested address

During handling of the above exception, another exception occurred:

Traceback (most recent call last):
  File "/home/airflow/.local/lib/python3.8/site-packages/airflow/models/taskinstance.py", line 824, in _handle_failure
    task_instance.email_alert(error, failure_context["task"])
  File "/home/airflow/.local/lib/python3.8/site-packages/airflow/models/taskinstance.py", line 2947, in email_alert
    _email_alert(task_instance=self, exception=exception, task=task)
  File "/home/airflow/.local/lib/python3.8/site-packages/airflow/models/taskinstance.py", line 1002, in _email_alert
    send_email(task.email, subject, html_content_err)
  File "/home/airflow/.local/lib/python3.8/site-packages/airflow/utils/email.py", line 80, in send_email
    return backend(
  File "/home/airflow/.local/lib/python3.8/site-packages/airflow/utils/email.py", line 154, in send_email_smtp
    send_mime_email(e_from=mail_from, e_to=recipients, mime_msg=msg, conn_id=conn_id, dryrun=dryrun)
  File "/home/airflow/.local/lib/python3.8/site-packages/airflow/utils/email.py", line 272, in send_mime_email
    smtp_conn = _get_smtp_connection(smtp_host, smtp_port, smtp_timeout, smtp_ssl)
  File "/home/airflow/.local/lib/python3.8/site-packages/airflow/utils/email.py", line 316, in _get_smtp_connection
    return smtplib.SMTP(host=host, port=port, timeout=timeout)
  File "/usr/local/lib/python3.8/smtplib.py", line 255, in __init__
    (code, msg) = self.connect(host, port)
  File "/usr/local/lib/python3.8/smtplib.py", line 339, in connect
    self.sock = self._get_socket(host, port, self.timeout)
  File "/usr/local/lib/python3.8/smtplib.py", line 310, in _get_socket
    return socket.create_connection((host, port), timeout,
  File "/usr/local/lib/python3.8/socket.py", line 808, in create_connection
    raise err
  File "/usr/local/lib/python3.8/socket.py", line 796, in create_connection
    sock.connect(sa)
OSError: [Errno 99] Cannot assign requested address
[2024-01-06T08:42:41.546+0000] {standard_task_runner.py:107} ERROR - Failed to execute job 37 for task sleep (Bash command failed. The command returned a non-zero exit code 1.; 172)
[2024-01-06T08:42:41.584+0000] {local_task_job_runner.py:234} INFO - Task exited with return code 1
[2024-01-06T08:42:41.645+0000] {taskinstance.py:3281} INFO - 0 downstream tasks scheduled from follow-on schedule check
