[2024-01-05T04:26:11.536+0000] {scheduler_job_runner.py:781} ERROR - Executor reports task instance <TaskInstance: data_ds.print_date manual__2024-01-05T04:26:06.870485+00:00 [queued]> finished (failed) although the task says it's queued. (Info: None) Was the task killed externally?
